Workbook

Sheet ЦС и Ф
A1: Обслуживаемые устройства | B1: Значение для центра | C1: Измеритель | D1: N | E1: VN, TE | F1: T0,TE | H1: Обслуживаемые устройства | I1: Значение для филиала | J1: Измеритель | K1: N | L1: VN, TE | M1: T0,TE
A2: 1 | B2: 2 | C2: 3 | D2: 4 | E2: 5 | F2: 6 | H2: 1 | I2: 2 | J2: 3 | K2: 4 | L2: 5 | M2: 6
A3: Устройства проводной связи | H3: Устройства проводной связи
A4: Цифровая АТС, точек подкл. (незадейств./задейств.) | B4: 2800 | C4: 256 | D4: =B4/C4 -> 10.9375 | E4: =0.28*0.5 -> 0.14 | F4: =D4*E4 -> 1.53125 | H4: Цифровая АТС, точек подкл. (незадейств./задейств.) | I4: 1900 | J4: 256 | K4: =I4/J4 -> 7.421875 | L4: =0.2*0.5 -> 0.1 | M4: =K4*L4 -> 0.7421875
B5: 2300 | C5: 256 | D5: =B5/C5 -> 8.984375 | E5: 0.28 | F5: =D5*E5 -> 2.515625 | I5: 1200 | J5: 256 | K5: =I5/J5 -> 4.6875 | L5: 0.2 | M5: =K5*L5 -> 0.9375
A6: ЛАЗ с цифровыми оконечн. полукомпл., канал | B6: 540 | C6: 30 | D6: =B6/C6 -> 18 | E6: 0.28 | F6: =D6*E6 -> 5.04 | H6: ЛАЗ с цифровыми оконечн. полукомпл., канал | I6: 250 | J6: 30 | K6: =I6/J6 -> 8.3333333 | L6: 0.2 | M6: =K6*L6 -> 1.6666667
A7: Автоматическая цифровая ТС, точек подкл. | B7: 6000 | C7: 256 | D7: =B7/C7 -> 23.4375 | E7: 0.28 | F7: =D7*E7 -> 6.5625 | H7: Автоматическая цифровая ТС, точек подкл. | I7: 2500 | J7: 256 | K7: =I7/J7 -> 9.765625 | L7: 0.2 | M7: =K7*L7 -> 1.953125
A8: Факсимильные телеграфные аппараты, аппарат | B8: 35 | C8: 1 | D8: =B8/C8 -> 35 | E8: 0.06 | F8: =D8*E8 -> 2.1 | H8: Факсимильные телеграфные аппараты, аппарат | I8: 16 | J8: 1 | K8: =I8/J8 -> 16 | L8: 0.06 | M8: =K8*L8 -> 0.96
A9: Распорядит. станции связи, комплект (диспетчерской/постанционной) | B9: 5 | C9: 1 | D9: =B9/C9 -> 5 | E9: 0.03 | F9: =D9*E9 -> 0.15 | H9: Распорядит. станции связи, комплект (диспетчерской/постанционной) | I9: 2 | J9: 1 | K9: =I9/J9 -> 2 | L9: 0.03 | M9: =K9*L9 -> 0.06
B10: 2 | C10: 1 | D10: =B10/C10 -> 2 | E10: 0.03 | F10: =D10*E10 -> 0.06 | I10: 1 | J10: 1 | K10: =I10/J10 -> 1 | L10: 0.03 | M10: =K10*L10 -> 0.03
A11: Коммутаторы оперативно-технологической связи, номер | B11: 1200 | C11: 10 | D11: =B11/C11 -> 120 | E11: 0.02 | F11: =D11*E11 -> 2.4 | H11: Коммутаторы оперативно-технологической связи, номер | I11: 700 | J11: 10 | K11: =I11/J11 -> 70 | L11: 0.01 | M11: =K11*L11 -> 0.7
A12: Часы первичные/электрические вторичные, шт. | B12: 28 | C12: 1 | D12: =B12/C12 -> 28 | E12: 0.03 | F12: =D12*E12 -> 0.84 | H12: Часы первичные/электрические вторичные, шт. | I12: 15 | J12: 1 | K12: =I12/J12 -> 15 | L12: 0.03 | M12: =K12*L12 -> 0.45
B13: 175 | C13: 10 | D13: =B13/C13 -> 17.5 | E13: 0.07 | F13: =D13*E13 -> 1.225 | I13: 85 | J13: 10 | K13: =I13/J13 -> 8.5 | L13: 0.07 | M13: =K13*L13 -> 0.595
A14: Устройства радиосвязи | H14: Устройства радиосвязи
A15: Локомотивные радиостанции поездной радиосвязи, р/ст. («чужих»/«своих») | B15: 0 | C15: 10 | D15: =B15/C15 -> 0 | E15: 0.1 | F15: =D15*E15 -> 0 | H15: Локомотивные радиостанции поездной радиосвязи, р/ст. («чужих»/«своих») | I15: 0 | J15: 10 | K15: =I15/J15 -> 0 | L15: 0.1 | M15: =K15*L15 -> 0
B16: 450 | C16: 10 | D16: =B16/C16 -> 45 | E16: 0.44 | F16: =D16*E16 -> 19.8 | I16: 280 | J16: 10 | K16: =I16/J16 -> 28 | L16: 0.44 | M16: =K16*L16 -> 12.32
A17: Стационарные радиостанции поездной радиосвязи, р/ст. | B17: 95 | C17: 10 | D17: =B17/C17 -> 9.5 | E17: 0.41 | F17: =D17*E17 -> 3.895 | H17: Стационарные радиостанции поездной радиосвязи, р/ст. | I17: 44 | J17: 10 | K17: =I17/J17 -> 4.4 | L17: 0.41 | M17: =K17*L17 -> 1.804
A18: Радиостанции локомотивные станционной радиосв., р/ст. | B18: 25 | C18: 10 | D18: =B18/C18 -> 2.5 | E18: 0.3 | F18: =D18*E18 -> 0.75 | H18: Радиостанции локомотивные станционной радиосв., р/ст. | I18: 13 | J18: 10 | K18: =I18/J18 -> 1.3 | L18: 0.3 | M18: =K18*L18 -> 0.39
A19: Радиостанции стационар. станционной и ремон.-опер. радиосвязи и возимые, р/ст. | B19: 85 | C19: 10 | D19: =B19/C19 -> 8.5 | E19: 0.26 | F19: =D19*E19 -> 2.21 | H19: Радиостанции стационар. станционной и ремон.-опер. радиосвязи и возимые, р/ст. | I19: 46 | J19: 10 | K19: =I19/J19 -> 4.6 | L19: 0.26 | M19: =K19*L19 -> 1.196
A20: Речевые информаторы, комплект | B20: 53 | C20: 1 | D20: =B20/C20 -> 53 | E20: 0.05 | F20: =D20*E20 -> 2.65 | H20: Речевые информаторы, комплект | I20: 29 | J20: 1 | K20: =I20/J20 -> 29 | L20: 0.05 | M20: =K20*L20 -> 1.45
A21: Автоматизированные устройства для обслуживания пассажиров | H21: Автоматизированные устройства для обслуживания пассажиров
A22: Информационные системы отправл. поездов, знакомест | B22: 72 | C22: 100 | D22: =B22/C22 -> 0.72 | E22: 0.06 | F22: =D22*E22 -> 0.0432 | H22: Информационные системы отправл. поездов, знакомест | I22: 40 | J22: 100 | K22: =I22/J22 -> 0.4 | L22: 0.06 | M22: =K22*L22 -> 0.024
A23: Промыш. телевизионные установки, передающая камера | B23: 37 | C23: 1 | D23: =B23/C23 -> 37 | E23: 0.03 | F23: =D23*E23 -> 1.11 | H23: Промыш. телевизионные установки, передающая камера | I23: 18 | J23: 1 | K23: =I23/J23 -> 18 | L23: 0.03 | M23: =K23*L23 -> 0.54
A24: Переговорные устройства типа «пассажир – кассир», шт. | B24: 94 | C24: 100 | D24: =B24/C24 -> 0.94 | E24: 0.16 | F24: =D24*E24 -> 0.1504 | H24: Переговорные устройства типа «пассажир – кассир», шт. | I24: 42 | J24: 100 | K24: =I24/J24 -> 0.42 | L24: 0.16 | M24: =K24*L24 -> 0.0672
A25: Устройства вычислительной техники | H25: Устройства вычислительной техники
A26: Персональные ЭВМ, шт. | B26: 25 | C26: 10 | D26: =B26/C26 -> 2.5 | E26: 0.33 | F26: =D26*E26 -> 0.825 | H26: Персональные ЭВМ, шт. | I26: 14 | J26: 10 | K26: =I26/J26 -> 1.4 | L26: 0.33 | M26: =K26*L26 -> 0.462
A27: Модем, канал | B27: 7 | C27: 1 | D27: =B27/C27 -> 7 | E27: 0.02 | F27: =D27*E27 -> 0.14 | H27: Модем, канал | I27: 4 | J27: 1 | K27: =I27/J27 -> 4 | L27: 0.02 | M27: =K27*L27 -> 0.08
A28: Печатающее устройство, шт. | B28: 16 | C28: 1 | D28: =B28/C28 -> 16 | E28: 0.06 | F28: =D28*E28 -> 0.96 | H28: Печатающее устройство, шт. | I28: 10 | J28: 1 | K28: =I28/J28 -> 10 | L28: 0.06 | M28: =K28*L28 -> 0.6
A29: Дисплеи разного назначения, шт. | B29: 1 | C29: 1 | D29: =B29/C29 -> 1 | E29: 0.04 | F29: =D29*E29 -> 0.04 | H29: Дисплеи разного назначения, шт. | I29: 1 | J29: 1 | K29: =I29/J29 -> 1 | L29: 0.04 | M29: =K29*L29 -> 0.04
A30: Аппаратура передачи данных, комплект | B30: 13 | C30: 1 | D30: =B30/C30 -> 13 | E30: 0.48 | F30: =D30*E30 -> 6.24 | H30: Аппаратура передачи данных, комплект | I30: 5 | J30: 1 | K30: =I30/J30 -> 5 | L30: 0.48 | M30: =K30*L30 -> 2.4
E31: Сумма: | F31: =SUM(F26:F30)+SUM(F22:F24)+SUM(F15:F20)+SUM(F4:F13) -> 61.237975 | L31: Сумма: | M31: =SUM(M26:M30)+SUM(M22:M24)+SUM(M15:M20)+SUM(M4:M13) -> 29.467679
A33: Обслуживаемые устройства | B33: Значение для центра | C33: Измеритель | D33: N | E33: VN, TE | F33: T0,TE | H33: Обслуживаемые устройства | I33: Значение для филиала | J33: Измеритель | K33: N | L33: VN, TE | M33: T0,TE
A34: 1 | B34: 2 | C34: 3 | D34: 4 | E34: 5 | F34: 6 | H34: 1 | I34: 2 | J34: 3 | K34: 4 | L34: 5 | M34: 6
A35: Аппаратура ВЧ телефонирования: цифровые оконечные полукомплекты, канал | B35: =5+3 -> 8 | C35: 30 | D35: =B35/C35 -> 0.26666667 | E35: 0.28 | F35: =D35*E35 -> 0.074666667 | H35: Аппаратура ВЧ телефонирования: цифровые оконечные полукомплекты, канал | I35: 5 | J35: 30 | K35: =I35/J35 -> 0.16666667 | L35: 0.2 | M35: =K35*L35 -> 0.033333333
A36: Распорядительные станции постанционной связи, комплект | B36: 2 | C36: 1 | D36: =B36/C36 -> 2 | E36: 0.03 | F36: =D36*E36 -> 0.06 | H36: Распорядительные станции постанционной связи, комплект | I36: 2 | J36: 1 | K36: =I36/J36 -> 2 | L36: 0.03 | M36: =K36*L36 -> 0.06
A37: Телефонные аппараты, аппарат | B37: 15 | C37: 100 | D37: =B37/C37 -> 0.15 | E37: 0.25 | F37: =D37*E37 -> 0.0375 | H37: Телефонные аппараты, аппарат | I37: 15 | J37: 100 | K37: =I37/J37 -> 0.15 | L37: 0.25 | M37: =K37*L37 -> 0.0375
A38: Промежуточные пункты ОТС, промпункт | B38: 1 | C38: 100 | D38: =B38/C38 -> 0.01 | E38: 1.14 | F38: =D38*E38 -> 0.0114 | H38: Промежуточные пункты ОТС, промпункт | I38: 1 | J38: 100 | K38: =I38/J38 -> 0.01 | L38: 1.14 | M38: =K38*L38 -> 0.0114
A39: Аппаратура связи совещаний на станциях, комплект | B39: 2 | C39: 1 | D39: =B39/C39 -> 2 | E39: 0.1 | F39: =D39*E39 -> 0.2 | H39: Аппаратура связи совещаний на станциях, комплект | I39: 2 | J39: 1 | K39: =I39/J39 -> 2 | L39: 0.1 | M39: =K39*L39 -> 0.2
A40: Радиостанции стационарные ПРС, р/ст | B40: 1 | C40: 10 | D40: =B40/C40 -> 0.1 | E40: 0.41 | F40: =D40*E40 -> 0.041 | H40: Радиостанции стационарные ПРС, р/ст | I40: 1 | J40: 10 | K40: =I40/J40 -> 0.1 | L40: 0.41 | M40: =K40*L40 -> 0.041
A41: Радиостанции стационарные СРС р/ст | B41: 1 | C41: 10 | D41: =B41/C41 -> 0.1 | E41: 0.3 | F41: =D41*E41 -> 0.03 | H41: Радиостанции стационарные СРС р/ст | I41: 1 | J41: 10 | K41: =I41/J41 -> 0.1 | L41: 0.3 | M41: =K41*L41 -> 0.03
...

Sheet Др. ст.
A1: Обслуживаемые устройства | C1: Значение для линии I категории | D1: Измеритель | E1: N | F1: VN, TE | G1: T0,TE | H1: Количество станций | I1: Общая T0, TE | L1: Обслуживаемые устройства | M1: Значение для линии II категории | N1: Измеритель | O1: N | P1: VN, TE | Q1: T0,TE | R1: Количество станций | S1: Общая T0, TE | V1: Обслуживаемые устройства | X1: Значение для линии IV категории | Y1: Измеритель | Z1: N | AA1: VN, TE | AB1: T0,TE | AC1: Количество станций | AD1: Общая T0, TE
A2: 1 | C2: 2 | D2: 3 | E2: 4 | F2: 5 | G2: 6 | H2: 7 | I2: 8 | L2: 1 | M2: 2 | N2: 3 | O2: 4 | P2: 5 | Q2: 6 | R2: 7 | S2: 8 | V2: 1 | X2: 2 | Y2: 3 | Z2: 4 | AA2: 5 | AB2: 6 | AC2: 7 | AD2: 8
A3: Аппаратура ВЧ телефонирования: цифровые оконечные полукомплекты, канал | C3: 5 | D3: 30 | E3: =C3/D3 -> 0.16666667 | F3: 0.2 | G3: =E3*F3 -> 0.033333333 | H3: 15 | I3: =G3*H3 -> 0.5 | L3: Аппаратура ВЧ телефонирования: цифровые оконечные полукомплекты, канал | M3: 4 | N3: 30 | O3: =M3/N3 -> 0.13333333 | P3: 0.2 | Q3: =O3*P3 -> 0.026666667 | R3: 10 | S3: =Q3*R3 -> 0.26666667 | V3: Аппаратура ВЧ телефонирования: аналоговые оконечные полукомплекты, канал | X3: 2 | Y3: 30 | Z3: =X3/Y3 -> 0.066666667 | AA3: 0.19 | AB3: =Z3*AA3 -> 0.012666667 | AC3: 7 | AD3: =AB3*AC3 -> 0.088666667
A4: Распорядительные станции постанционной связи, комплект | C4: 2 | D4: 1 | E4: =C4/D4 -> 2 | F4: 0.03 | G4: =E4*F4 -> 0.06 | H4: 15 | I4: =G4*H4 -> 0.9 | L4: Распорядительные станции постанционной связи, комплект | M4: 2 | N4: 1 | O4: =M4/N4 -> 2 | P4: 0.03 | Q4: =O4*P4 -> 0.06 | R4: 10 | S4: =Q4*R4 -> 0.6 | V4: Распорядительные станции постанционной связи, комплект | X4: 2 | Y4: 1 | Z4: =X4/Y4 -> 2 | AA4: 0.03 | AB4: =Z4*AA4 -> 0.06 | AC4: 7 | AD4: =AB4*AC4 -> 0.42
A5: Телефонные аппараты, аппарат | C5: 15 | D5: 100 | E5: =C5/D5 -> 0.15 | F5: 0.25 | G5: =E5*F5 -> 0.0375 | H5: 15 | I5: =G5*H5 -> 0.5625 | L5: Телефонные аппараты, аппарат | M5: 12 | N5: 100 | O5: =M5/N5 -> 0.12 | P5: 0.25 | Q5: =O5*P5 -> 0.03 | R5: 10 | S5: =Q5*R5 -> 0.3 | V5: Телефонные аппараты, аппарат | X5: 5 | Y5: 100 | Z5: =X5/Y5 -> 0.05 | AA5: 0.25 | AB5: =Z5*AA5 -> 0.0125 | AC5: 7 | AD5: =AB5*AC5 -> 0.0875
A6: Промежуточные пункты ОТС, промпункт | C6: 1 | D6: 100 | E6: =C6/D6 -> 0.01 | F6: 1.14 | G6: =E6*F6 -> 0.0114 | H6: 15 | I6: =G6*H6 -> 0.171 | L6: Промежуточные пункты ОТС, промпункт | M6: 1 | N6: 100 | O6: =M6/N6 -> 0.01 | P6: 1.12 | Q6: =O6*P6 -> 0.0112 | R6: 10 | S6: =Q6*R6 -> 0.112 | V6: Промежуточные пункты ОТС, промпункт | X6: 1 | Y6: 100 | Z6: =X6/Y6 -> 0.01 | AA6: 1.11 | AB6: =Z6*AA6 -> 0.0111 | AC6: 7 | AD6: =AB6*AC6 -> 0.0777
A7: Аппаратура связи совещаний на станциях, комплект | C7: 2 | D7: 1 | E7: =C7/D7 -> 2 | F7: 0.1 | G7: =E7*F7 -> 0.2 | H7: 15 | I7: =G7*H7 -> 3 | L7: Аппаратура связи совещаний на станциях, комплект | M7: 2 | N7: 1 | O7: =M7/N7 -> 2 | P7: 0.1 | Q7: =O7*P7 -> 0.2 | R7: 10 | S7: =Q7*R7 -> 2 | V7: Аппаратура связи совещаний на станциях, комплект | X7: 2 | Y7: 1 | Z7: =X7/Y7 -> 2 | AA7: 0.1 | AB7: =Z7*AA7 -> 0.2 | AC7: 7 | AD7: =AB7*AC7 -> 1.4
A8: Радиостанции стационарные ПРС, р/ст | C8: 1 | D8: 10 | E8: =C8/D8 -> 0.1 | F8: 0.41 | G8: =E8*F8 -> 0.041 | H8: 15 | I8: =G8*H8 -> 0.615 | L8: Радиостанции стационарные ПРС, р/ст | M8: 1 | N8: 10 | O8: =M8/N8 -> 0.1 | P8: 0.41 | Q8: =O8*P8 -> 0.041 | R8: 10 | S8: =Q8*R8 -> 0.41 | V8: Радиостанции стационарные ПРС, р/ст | X8: 1 | Y8: 10 | Z8: =X8/Y8 -> 0.1 | AA8: 0.41 | AB8: =Z8*AA8 -> 0.041 | AC8: 7 | AD8: =AB8*AC8 -> 0.287
A9: Радиостанции стационарные СРС р/ст | C9: 1 | D9: 10 | E9: =C9/D9 -> 0.1 | F9: 0.3 | G9: =E9*F9 -> 0.03 | H9: 15 | I9: =G9*H9 -> 0.45 | L9: Радиостанции стационарные СРС р/ст | M9: 1 | N9: 10 | O9: =M9/N9 -> 0.1 | P9: 0.3 | Q9: =O9*P9 -> 0.03 | R9: 10 | S9: =Q9*R9 -> 0.3 | V9: Радиостанции стационарные СРС р/ст | X9: 1 | Y9: 10 | Z9: =X9/Y9 -> 0.1 | AA9: 0.3 | AB9: =Z9*AA9 -> 0.03 | AC9: 7 | AD9: =AB9*AC9 -> 0.21
A10: Аппаратура регистрации служебных переговоров, комплект | C10: 2 | D10: 1 | E10: =C10/D10 -> 2 | F10: 0.07 | G10: =E10*F10 -> 0.14 | H10: 16 | I10: =G10*H10 -> 2.24 | L10: Аппаратура регистрации служебных переговоров, комплект | M10: 2 | N10: 1 | O10: =M10/N10 -> 2 | P10: 0.07 | Q10: =O10*P10 -> 0.14 | R10: 10 | S10: =Q10*R10 -> 1.4 | V10: Аппаратура регистрации служебных переговоров, комплект | X10: 2 | Y10: 1 | Z10: =X10/Y10 -> 2 | AA10: 0.07 | AB10: =Z10*AA10 -> 0.14 | AC10: 7 | AD10: =AB10*AC10 -> 0.98
A11: Усилители 1000 Вт, усилитель | B11: Уч. ст. | C11: 2 | D11: 1 | E11: =C11/D11 -> 2 | F11: 0.08 | G11: =E11*F11 -> 0.16 | H11: 2 | I11: =G11*H11 -> 0.32 | L11: Усилители 1000 Вт, усилитель | M11: 1 | N11: 1 | O11: =M11/N11 -> 1 | P11: 0.07 | Q11: =O11*P11 -> 0.07 | R11: 10 | S11: =Q11*R11 -> 0.7 | V11: Усилители 1000 Вт, усилитель | W11: Пр. ст. | X11: 1 | Y11: 1 | Z11: =X11/Y11 -> 1 | AA11: 0.07 | AB11: =Z11*AA11 -> 0.07 | AC11: 5 | AD11: =AB11*AC11 -> 0.35
B12: Пр. ст. | C12: 1 | D12: 1 | E12: =C12/D12 -> 1 | F12: 0.08 | G12: =E12*F12 -> 0.08 | H12: 14 | I12: =G12*H12 -> 1.12 | L12: Усилители 600 Вт, усилитель | M12: 1 | N12: 1 | O12: =M12/N12 -> 1 | P12: 0.07 | Q12: =O12*P12 -> 0.07 | R12: 10 | S12: =Q12*R12 -> 0.7 | V12: Усилители 600 Вт, усилитель | W12: Пр. ст. | X12: 1 | Y12: 1 | Z12: =X12/Y12 -> 1 | AA12: 0.07 | AB12: =Z12*AA12 -> 0.07 | AC12: 5 | AD12: =AB12*AC12 -> 0.35
A13: Усилители 600 Вт, усилитель | B13: Пр. ст. | C13: 1 | D13: 1 | E13: =C13/D13 -> 1 | F13: 0.08 | G13: =E13*F13 -> 0.08 | H13: 14 | I13: =G13*H13 -> 1.12 | L13: Громкоговорители, шт. | M13: =2*INT(3000/120) -> 50 | N13: 10 | O13: =M13/N13 -> 5 | P13: 0.03 | Q13: =O13*P13 -> 0.15 | R13: 10 | S13: =Q13*R13 -> 1.5 | W13: Тупик. ст. | X13: 2 | Y13: 1 | Z13: =X13/Y13 -> 2 | AA13: 0.07 | AB13: =Z13*AA13 -> 0.14 | AC13: 2 | AD13: =AB13*AC13 -> 0.28
A14: Громкоговорители, шт. | B14: Уч. ст. | C14: =2*INT(4000/120) -> 66 | D14: 10 | E14: =C14/D14 -> 6.6 | F14: 0.03 | G14: =E14*F14 -> 0.198 | H14: 2 | I14: =G14*H14 -> 0.396 | L14: Звуковые колонки (переговорные устройства парковой связи), шт. | M14: =INT(3000/120)+INT(13/2) -> 31 | N14: 10 | O14: =M14/N14 -> 3.1 | P14: 0.03 | Q14: =O14*P14 -> 0.093 | R14: 10 | S14: =Q14*R14 -> 0.93 | V14: Громкоговорители, шт. | W14: Пр. ст. | X14: =2*INT(3000/120) -> 50 | Y14: 10 | Z14: =X14/Y14 -> 5 | AA14: 0.03 | AB14: =Z14*AA14 -> 0.15 | AC14: 5 | AD14: =AB14*AC14 -> 0.75
B15: Пр. ст. | C15: =2*INT(3000/120) -> 50 | D15: 10 | E15: =C15/D15 -> 5 | F15: 0.03 | G15: =E15*F15 -> 0.15 | H15: 14 | I15: =G15*H15 -> 2.1 | L15: Радиостанции носимые, р/ст. | M15: 10 | N15: 10 | O15: =M15/N15 -> 1 | P15: 0.15 | Q15: =O15*P15 -> 0.15 | R15: 10 | S15: =Q15*R15 -> 1.5 | V15: Звуковые колонки (переговорные устройства парковой связи), шт. | W15: Пр. ст. | X15: =INT(3000/120)+INT(4/2) -> 27 | Y15: 10 | Z15: =X15/Y15 -> 2.7 | AA15: 0.03 | AB15: =Z15*AA15 -> 0.081 | AC15: 5 | AD15: =AB15*AC15 -> 0.405
A16: Звуковые колонки (переговорные устройства парковой связи), шт. | B16: Уч. ст. | C16: =INT(4000/120)+INT(97/2) -> 81 | D16: 10 | E16: =C16/D16 -> 8.1 | F16: 0.03 | G16: =E16*F16 -> 0.243 | H16: 2 | I16: =G16*H16 -> 0.486 | R16: Сумма: | S16: =SUM(S3:S15) -> 10.718667 | W16: Тупик. ст. | X16: =INT(3000/120)+INT(7/2) -> 28 | Y16: 11 | Z16: =X16/Y16 -> 2.5454545 | AA16: 0.03 | AB16: =Z16*AA16 -> 0.076363636 | AC16: 2 | AD16: =AB16*AC16 -> 0.15272727
B17: Пр. ст. | C17: =INT(3000/120)+INT(15/2) -> 32 | D17: 10 | E17: =C17/D17 -> 3.2 | F17: 0.03 | G17: =E17*F17 -> 0.096 | H17: 14 | I17: =G17*H17 -> 1.344 | V17: Радиостанции носимые, р/ст. | W17: Пр. ст. | X17: 10 | Y17: 10 | Z17: =X17/Y17 -> 1 | AA17: 0.15 | AB17: =Z17*AA17 -> 0.15 | AC17: 5 | AD17: =AB17*AC17 -> 0.75
A18: Радиостанции носимые, р/ст. | B18: Уч. ст. | C18: 40 | D18: 10 | E18: =C18/D18 -> 4 | F18: 0.15 | G18: =E18*F18 -> 0.6 | H18: 2 | I18: =G18*H18 -> 1.2 | W18: Тупик. ст. | X18: 10 | Y18: 10 | Z18: =X18/Y18 -> 1 | AA18: 0.15 | AB18: =Z18*AA18 -> 0.15 | AC18: 2 | AD18: =AB18*AC18 -> 0.3
B19: Пр. ст. | C19: 10 | D19: 10 | E19: =C19/D19 -> 1 | F19: 0.15 | G19: =E19*F19 -> 0.15 | H19: 14 | I19: =G19*H19 -> 2.1 | AC19: Сумма: | AD19: =SUM(AD3:AD18) -> 6.8885939
H20: Сумма: | I20: =SUM(I3:I19) -> 18.6245

Sheet Линии связи
A1: Обслуживаемые устройства | C1: Значение четверок жил (проводов/волокон) для линии I категории | D1: Длина станции или перегона, км | E1: Длина линии связи, км | F1: Измеритель | G1: N | H1: VN, TE | I1: Пожильная (попроводная/поволоконная) T0 ,TE | J1: Общая T0,TE | L1: Обслуживаемые устройства | N1: Значение четверок (пар) жил для линии II категории | O1: Длина станции или перегона, км | P1: Длина линии связи, км | Q1: Измеритель | R1: N | S1: VN, TE | T1: Почетверочная T0 ,TE | U1: Общая T0,TE | W1: Обслуживаемые устройства | Y1: Значение четверок (пар) жил для линии IV категории | Z1: Длина станции или перегона, км | AA1: Длина линии связи, км | AB1: Измеритель | AC1: N | AD1: VN, TE | AE1: Почетверочная T0 ,TE | AF1: Общая T0,TE
A2: 1 | C2: 2 | D2: 3 | E2: 4 | F2: 5 | G2: 6 | H2: 7 | I2: 8 | J2: 9 | L2: 1 | N2: 2 | O2: 3 | P2: 4 | Q2: 5 | R2: 6 | S2: 7 | T2: 8 | U2: 9 | W2: 1 | Y2: 2 | Z2: 3 | AA2: 4 | AB2: 5 | AC2: 6 | AD2: 7 | AE2: 8 | AF2: 9
A3: Местные кабельные линии связи, км | B3: Уч. ст. | C3: 6 | D3: 4 | E3: =D3*2 -> 8 | F3: 10 | G3: =E3/F3 -> 0.8 | H3: 0.08 | I3: =G3*H3 -> 0.064 | J3: =I3*C3 -> 0.384 | L3: Местные двухкабельные линии связи, км | M3: Уч. ст. | N3: 6 | O3: 4 | P3: =O3*1 -> 4 | Q3: 10 | R3: =P3/Q3 -> 0.4 | S3: 0.08 | T3: =R3*S3 -> 0.032 | U3: =T3*N3 -> 0.192 | W3: Местные двухкабельные линии связи, км | X3: Уч. ст. | Y3: 6 | Z3: 4 | AA3: =Z3*0 -> 0 | AB3: 10 | AC3: =AA3/AB3 -> 0 | AD3: 0.08 | AE3: =AC3*AD3 -> 0 | AF3: =AE3*Y3 -> 0
B4: Пр. и тупик. ст. | C4: 4 | D4: 3 | E4: =D4*14 -> 42 | F4: 10 | G4: =E4/F4 -> 4.2 | H4: 0.08 | I4: =G4*H4 -> 0.336 | J4: =I4*C4 -> 1.344 | M4: Пр. и тупик. ст. | N4: 4 | O4: 3 | P4: =O4*10 -> 30 | Q4: 10 | R4: =P4/Q4 -> 3 | S4: 0.08 | T4: =R4*S4 -> 0.24 | U4: =T4*N4 -> 0.96 | X4: Пр. и тупик. ст. | Y4: 4 | Z4: 3 | AA4: =Z4*7 -> 21 | AB4: 10 | AC4: =AA4/AB4 -> 2.1 | AD4: 0.08 | AE4: =AC4*AD4 -> 0.168 | AF4: =AE4*Y4 -> 0.672
A5: Местные воздушные линии связи, км | B5: Уч. ст. | C5: 3 | D5: 4 | E5: =D5*2 -> 8 | F5: 10 | G5: =E5/F5 -> 0.8 | H5: 0.08 | I5: =G5*H5 -> 0.064 | J5: =I5*C5 -> 0.192 | L5: Магистральные кабельные линии связи, км | N5: 7 | O5: 29 | P5: =O5*12 -> 348 | Q5: 10 | R5: =P5/Q5 -> 34.8 | S5: 0.2 | T5: =R5*S5 -> 6.96 | U5: =T5*N5 -> 48.72 | W5: Магистральные кабельные линии связи, км | Y5: 4 | Z5: 39 | AA5: =Z5*7 -> 273 | AB5: 10 | AC5: =AA5/AB5 -> 27.3 | AD5: 0.2 | AE5: =AC5*AD5 -> 5.46 | AF5: =AE5*Y5 -> 21.84
B6: Пр. и тупик. ст. | C6: 3 | D6: 3 | E6: =D6*14 -> 42 | F6: 10 | G6: =E6/F6 -> 4.2 | H6: 0.08 | I6: =G6*H6 -> 0.336 | J6: =I6*C6 -> 1.008 | T6: Сумма: | U6: =SUM(U3:U5) -> 49.872 | AE6: Сумма: | AF6: =SUM(AF3:AF5) -> 22.512
A7: Магистральные воздушные линии связи, проводо-км | C7: 14 | D7: 29 | E7: =D7*17 -> 493 | F7: 100 | G7: =E7/F7 -> 4.93 | H7: 0.18 | I7: =G7*H7 -> 0.8874 | J7: =I7*C7 -> 12.4236
A8: ВОЛС, км | C8: 16 | D8: 29 | E8: =D8*17 -> 493 | F8: 10 | G8: =E8/F8 -> 49.3 | H8: 0.22 | I8: =G8*H8 -> 10.846 | J8: =I8*C8 -> 173.536
I9: Сумма: | J9: =SUM(J3:J8) -> 188.8876

Sheet Полный объем работ
A1: ЦС | B1: ='ЦС и Ф'!$F$31 -> 61.237975 | D1: Общая длина дорог, км: | E1: =286+253+84+125+253+210 -> 1211 | F1: превышение 600 км
A2: доп. ЦС | B2: ='ЦС и Ф'!$F$48 -> 2.0825667 | D2: Максимальное плечо, км: | E2: 286 | F2: нет превышения 300 км
A3: Ф | B3: ='ЦС и Ф'!$M$31 -> 29.467679 | D3: 30,55% от T0, ТЕ = | E3: =0.3055*B11 -> 119.79352
A4: доп. Ф | B4: ='ЦС и Ф'!$M$48 -> 1.8312333 | D4: 0% от T0, ТЕ = | E4: =0*B11 -> 0
A5: Оборудование на линиях I категории | B5: ='Др. ст.'!$I$20 -> 18.6245 | D5: Общее количество баллов регионального центра связи = | E5: =B11+E3+E4 -> 511.91633 | F5: Группа регионального ЦС - III
A6: Оборудование на линиях II категории | B6: ='Др. ст.'!$S$16 -> 10.718667
A7: Оборудование на линиях IV категории | B7: ='Др. ст.'!$AD$19 -> 6.8885939
A8: Оборудование ЛС на линиях I категории | B8: ='Линии связи'!$J$9 -> 188.8876
A9: Оборудование ЛС на линиях II категории | B9: ='Линии связи'!$U$6 -> 49.872
A10: Оборудование ЛС на линиях IV категории | B10: ='Линии связи'!$AF$6 -> 22.512
A11: Общая сумма T0, ТЕ = | B11: =SUM(B1:B10) -> 392.12281 | C11: (в месяц)

Sheet Численность ДС
A1: Бригада - 5 или 10
A2: Объем работ и количество человек должно быть равным
A3: ЛПУ - от 3 до 5 бригад
A4: РЦСС (без Н) | D4: Центр связи (ст. А) | L4: Филиал (ст.В)
D5: Обслуживаемые устройства связи | E5: Исполнитель | F5: Измеритель | G5: Норма обслуживания, Vч | H5: N | I5: Нормативная численность | L5: Обслуживаемые устройства связи | M5: Исполнитель | N5: Измеритель | O5: Норма обслуживания, Vч | P5: N | Q5: Нормативная численность
I6: РЦСС | J6: РЦСН | Q6: РЦСС | R6: РЦСН
D7: Бригада по обслуживанию устройств АТС и ЛАЗа: РЦСС-1 | L7: Бригада по обслуживанию устройств АТС и ЛАЗа: РЦСС-4
D8: Цифровые автоматические телефонные станции в дистанции при НОД | E8: РЦСН | F8: АТС 3400/5505 | G8: 1 | H8: АТС 2800/2300 | I8: 1 | J8: 2 | L8: Цифровые автоматические телефонные станции в дистанции при НОД | M8: РЦСН | N8: АТС 3400/5505 | O8: 1 | P8: АТС 1900/1200 | Q8: 1 | R8: 1
D9: Телефонные аппараты | E9: РЦСН | F9: Аппарат | G9: 2100 | H9: =0.5*2300 -> 1150 | J9: 1 | L9: Телефонные аппараты | M9: РЦСН | N9: Аппарат | O9: 2100 | P9: =0.5*1200 -> 600 | R9: 1
D10: Аппаратура цифрового оконечного оборудования с учетом измерения аппаратуры ВЧ телефонирования | E10: РЦСН | F10: Канал | G10: 310 | H10: 540 | J10: 2 | L10: Аппаратура цифрового оконечного оборудования с учетом измерения аппаратуры ВЧ телефонирования | M10: РЦСН | N10: Канал | O10: 310 | P10: 250 | R10: 1
D11: Распорядительные станции диспетчерской связи (аппаратура ОТС) | E11: РЦСН | F11: Комплект | G11: 13 | H11: 5 | J11: 1 | L11: Распорядительные станции диспетчерской связи (аппаратура ОТС) | M11: РЦСН | N11: Комплект | O11: 13 | P11: 2 | R11: 1
D12: Аппаратура связи совещаний | E12: РЦСН | F12: Комплект | G12: 5 | H12: 2 | J12: 1 | L12: Аппаратура связи совещаний | M12: РЦСН | N12: Комплект | O12: 5 | P12: 2 | R12: 1
D13: Итого по бригаде: | I13: 1 | J13: =SUM(J8:J12) -> 7 | L13: Итого по бригаде: | Q13: 1 | R13: =SUM(R8:R12) -> 5
D14: Бригада по обслуживанию устройств ТС: РЦСС-2 | L14: Бригада по обслуживанию устройств ТС: РЦСС-5
D15: Автоматизированное рабочее место телеграфиста (телефониста) | E15: РЦСН | F15: АРМ | G15: 12 | H15: =58 -> 58 | I15: 1 | J15: 5 | L15: Автоматизированное рабочее место телеграфиста (телефониста) | M15: РЦСН | N15: АРМ | O15: 12 | P15: =600/10 -> 60 | Q15: 1 | R15: =60/12 -> 5
D16: Итого по бригаде: | I16: 1 | J16: =SUM(J15:J15) -> 5 | L16: Итого по бригаде: | Q16: 1 | R16: =SUM(R15:R15) -> 5
D17: Бригада по обслуживанию устройств ТС: РЦСС-3 | L17: Итого явочная численность, Чяв | Q17: 2 | R17: =R16+R13 -> 10
D18: Автоматизированное рабочее место телеграфиста (телефониста) | E18: РЦСН | F18: АРМ | G18: 12 | H18: =57 -> 57 | I18: 1 | J18: 5 | L18: Итого списочная численность с учетом Kсп | Q18: 2 | R18: =R17*1.12 -> 11.2
D19: Итого по бригаде: | I19: 1 | J19: 5 | L19: Всего по дому связи станции А | Q19: 2 | R19: 12
D20: Итого явочная численность, Чяв | I20: 3 | J20: =J19+J16+J13 -> 17
D21: Итого списочная численность с учетом Kсп | I21: 3 | J21: =J20*1.12 -> 19.04
D22: Всего по дому связи станции А | I22: 3 | J22: 20

Sheet Численность штата ЛПУ ПС
A1: 1 филиал = 2 заместителя
A2: 1 и 2 группа - глав инженер | B2: Станции | C2: Обслуживаемые устройства связи | D2: Исполнитель | E2: Измеритель | F2: Норма обслуживания | G2: N | H2: Нормативная численность | L2: Номер ЛПУ связи | M2: Обслуживаемый участок старшего электромеханика (РЦСС), номер и границы обслуживания | O2: Списочная численность, чел
H3: РЦСС | I3: РЦСН | J3: РЦСМ | O3: РЦСС | P3: РЦСН | Q3: РЦСМ
B4: Бригада по обслуживанию устройств ЛПУ и обслуживанию и централизованной замене устройств проводной связи: РЦСС-6 | L4: 3 | M4: 6 | N4: Устройства ЛПУ, ст. А (ЦУ), Б, С1-С14, С18-С19 | O4: =H5+H17+H36+H64+H69 -> 5 | P4: =(I15+I20+I48+I67+I72)*1.12 -> 35.84 | Q4: =(J15+J20+J48+J67+J72)*1.12 -> 7.84
B5: ст. А, Б, С1-С14 | C5: Аппаратура цифрового оконечного оборудования с учентом измерения аппаратуры ВЧ телефонирования | D5: РЦСН | E5: Канал | F5: 310 | G5: =15*5 -> 75 | H5: 1 | I5: 1 | J5: - | M5: 7
C6: Аппаратура аналогового оконечного оборудования с учентом измерения аппаратуры ВЧ телефонирования | D6: РЦСН | E6: Канал | F6: 100 | G6: 0 | I6: 0 | J6: - | M6: 9
C7: Аппаратура связи совещания | D7: РЦСН | E7: Комплект | F7: 16 | G7: =2*14+4+7 -> 39 | I7: 3 | J7: - | M7: 11
C8: Телефонные аппараты | D8: РЦСН | E8: аппарат | F8: 2100 | G8: =15*15+(2300*0.5) -> 1375 | I8: 1 | J8: - | M8: 12
C9: Коммутатор оперативно-технологической и станционно-распорядительной связи | D9: РЦСН | E9: номеров | F9: 1450 | G9: =1200 -> 1200 | I9: 1 | J9: - | L9: Итого по ЛПУ связи 3: | O9: 5 | P9: 36 | Q9: 8
C10: Коммутаторы междугородние и местные | D10: РЦСН | E10: коммутатор | F10: 16 | G10: 6 | I10: 1 | J10: - | L10: Всего по ЛПУ связи 3: | O10: =O9+P9+Q9 -> 49
C11: КЛМС | D11: РЦСН | E11: пара жил*км | F11: 3700 | G11: =8+42 -> 50 | I11: 1 | J11: - | L11: 4 | M11: 8 | N11: Устройства ЛПУ, ст. В (Ф), С15-С17, С20-С26, С27-С31 | O11: =H34+H62+H77 -> 3 | P11: =(I34+I62+I77)*1.12 -> 22.4 | Q11: =(J34+J62+J77)*1.12 -> 4.48
D12: РЦСМ | E12: пара жил*км | F12: 4950 | G12: =8+42 -> 50 | I12: - | J12: 1 | M12: 10
C13: КЛС | D13: РЦСН | E13: пара жил*км | F13: 3100 | G13: 0 | I13: 0 | J13: - | M13: 13
D14: РЦСМ | E14: пара жил*км | F14: 4600 | G14: 0 | I14: - | J14: 0 | L14: Итого по ЛПУ связи 4: | O14: 3 | P14: 23 | Q14: 5
B15: Итого по бригаде (явочная/списочная) численность: | H15: 1 | I15: =SUM(I5:I14) -> 8 | J15: =SUM(J5:J14) -> 1 | L15: Всего по ЛПУ связи 4: | O15: =O14+P14+Q14 -> 31
B16: Бригада по обслуживанию и централизованной замене устройств проводной связи и волоконно-оптических линий связи: РЦСС-7
B17: ст. А, Б, С1-С14 | C17: ВЛС до 16 проводов | D17: РЦСН | E17: км линий | F17: 150 | G17: 493 | H17: 1 | I17: 4 | J17: -
D18: РЦСМ | E18: км линий | F18: 140 | G18: 493 | I18: - | J18: 4
C19: ВОЛС | D19: РЦСН | E19: волокно*км | F19: 1000 | G19: 493 | I19: 1 | J19: -
B20: Итого по бригаде (явочная/списочная) численность: | H20: 1 | I20: =SUM(I17:I19) -> 5 | J20: =SUM(J17:J19) -> 4
B21: Бригада по обслуживанию устройств ЛПУ и обслуживанию и централизованной замене устройств проводной связи: РЦСС-8
B22: ст. В, С15-С17, С20-С26 | C22: Аппаратура цифрового оконечного оборудования с учентом измерения аппаратуры ВЧ телефонирования | D22: РЦСН | E22: Канал | F22: 325 | G22: =4*11 -> 44 | H22: 1 | I22: 1 | J22: -
C23: Аппаратура аналогового оконечного оборудования с учентом измерения аппаратуры ВЧ телефонирования | D23: РЦСН | E23: Канал | F23: 105 | G23: 0 | I23: 0 | J23: -
C24: Аппаратура связи совещания | D24: РЦСН | E24: Комплект | F24: 16 | G24: =4+10*2 -> 24 | I24: 2 | J24: -
C25: Телефонные аппараты | D25: РЦСН | E25: аппарат | F25: 2100 | G25: =1200*0.5+12*10 -> 720 | I25: 1 | J25: -
C26: Коммутатор оперативно-технологической и станционно-распорядительной связи | D26: РЦСН | E26: номеров | F26: 1500 | G26: 700 | I26: 1 | J26: -
C27: Коммутаторы междугородние и местные | D27: РЦСН | E27: коммутатор | F27: 17 | G27: 3 | I27: 1 | J27: -
C28: КЛМС | D28: РЦСН | E28: пара жил*км | F28: 3750 | G28: =4+30 -> 34 | I28: 1 | J28: -
D29: РЦСМ | E29: пара жил*км | F29: 5000 | G29: =4+30 -> 34 | I29: - | J29: 1
C30: КЛС | D30: РЦСН | E30: пара жил*км | F30: 3200 | G30: 348 | I30: 1 | J30: -
D31: РЦСМ | E31: пара жил*км | F31: 4700 | G31: 348 | I31: - | J31: 1
C32: ВЛС до 16 проводов | D32: РЦСН | E32: км линий | F32: 155 | G32: 0 | I32: =G32/F32 -> 0 | J32: -
D33: РЦСМ | E33: км линий | F33: 145 | G33: 0 | I33: - | J33: =G33/F33 -> 0
B34: Итого по бригаде (явочная/списочная) численность: | H34: 1 | I34: =SUM(I22:I33) -> 8 | J34: =SUM(J22:J33) -> 2
B35: Бригада по обслуживанию устройств ЛПУ и обслуживанию и централизованной замене устройств проводной связи: РЦСС-9
B36: С18-С19 | C36: Аппаратура цифрового оконечного оборудования с учентом измерения аппаратуры ВЧ телефонирования | D36: РЦСН | E36: Канал | F36: 355 | G36: 0 | H36: 1 | I36: 0 | J36: -
C37: Аппаратура аналогового оконечного оборудования с учентом измерения аппаратуры ВЧ телефонирования | D37: РЦСН | E37: Канал | F37: 115 | G37: =2*2 -> 4 | I37: 1 | J37: -
C38: Аппаратура связи совещания | D38: РЦСН | E38: Комплект | F38: 16 | G38: =2*2 -> 4 | I38: 1 | J38: -
C39: Телефонные аппараты | D39: РЦСН | E39: аппарат | F39: 2100 | G39: =5*2 -> 10 | I39: 1 | J39: -
C40: Коммутатор оперативно-технологической и станционно-распорядительной связи | D40: РЦСН | E40: номеров | F40: 1600 | G40: 0 | I40: =G40/F40 -> 0 | J40: -
...

Sheet ч.ш. ЛПУ радиосвязи
B2: Станции | C2: Обслуживаемые устройства связи | D2: Исполнитель | E2: Измеритель | F2: Норма обслуживания | G2: N | H2: Нормативная численность | L2: Номер ЛПУ связи | M2: Обслуживаемый участок старшего электромеханика (РЦСС), номер и границы обслуживания | O2: Списочная численность, чел
H3: РЦСС | I3: РЦСН | J3: РЦСМ | O3: РЦСС | P3: РЦСН | Q3: РЦСМ
B4: Бригада по обслуживанию устройств ПРС: РЦСС - 14 | L4: 3 | M4: 14 | N4: ст. А (ЦУ), Б, С1-С14, С18-С19
B5: ст. А, Б, С1-С14 | C5: Устройства поездной радиосвязи | D5: РЦСН | E5: Р/ст. локомот. "своих" | F5: 60 | G5: =450 -> 450 | H5: 1 | I5: 8 | J5: - | M5: 15
D6: РЦСН | E6: Распоряд. станция | F6: 105 | G6: =5+2+14*2 -> 35 | I6: 1 | J6: - | M6: 16
D7: РЦСН | E7: Р/ст. стационар. | F7: 45 | G7: =95+14 -> 109 | I7: 1 | J7: - | M7: 17
B8: Итого по бригаде (явочная/списочная) численность: | H8: =SUM(H5) -> 1 | I8: =SUM(I5:I7) -> 10 | J8: 0 | M8: 18
B9: Бригада по обслуживанию устройств ПРС и СРС РОРС: РЦСС-15 | M9: 19
B10: ст. А, Б, С1-С14 | C10: Устройства поездной радиосвязи | D10: РЦСН | E10: Р/ст. стационар. | F10: 45 | G10: =95+14 -> 109 | H10: 1 | I10: 2 | J10: - | M10: 20
C11: Радиостанция локомотивная | D11: РЦСН | E11: Р/ст. | F11: 60 | G11: =25+14 -> 39 | I11: 1 | J11: - | M11: 21
C12: Распорядительные станции | D12: РЦСН | E12: Станция | F12: 80 | G12: =5+2 -> 7 | I12: 1 | J12: - | M12: 22
C13: Радиостанция стационарная | D13: РЦСН | E13: Р/ст. | F13: 75 | G13: =95+14 -> 109 | I13: 2 | J13: - | M13: 23
C14: Усилитель 600, 1000 Вт | D14: РЦСН | E14: Усилитель | F14: 20 | G14: =2+2+14+14 -> 32 | I14: 2 | J14: - | M14: 29
C15: Аппаратура для регистрации служебных разговоров | D15: РЦСН | E15: Комплект | F15: 16 | G15: =7+4+2*14 -> 39 | I15: 2 | J15: - | M15: 30
B16: Итого по бригаде (явочная/списочная) численность: | H16: 1 | I16: 10 | J16: 0 | L16: Итого по ЛПУ связи 3:
B17: Бригада по обслуживанию устройств СРС РОРС: РЦСС-16 | L17: Всего по ЛПУ связи 3:
B18: ст. А, Б, С1-С14 | C18: Радиостанция носимая | D18: РЦСМ | E18: Р/ст. | F18: 200 | G18: =40+40+14*10 -> 220 | H18: 1 | I18: - | J18: 2 | L18: 4 | M18: 24 | N18: ст. В (Ф), С15-С17, С20-С26, С27-С31
C19: Громкоговорители и звуковые колонки | D19: РЦСМ | E19: Устройство | F19: 50 | G19: 221 | I19: - | J19: 5 | M19: 25
C20: Речевые информаторы | D20: РЦСМ | E20: Комплект | F20: 25 | G20: 53 | I20: - | J20: 3 | M20: 26
B21: Итого по бригаде (явочная/списочная) численность: | H21: 1 | I21: 0 | J21: 10 | M21: 27
B22: Бригада по обслуживанию устройств СРС РОРС: РЦСС-17 | M22: 28
B23: ст. А, Б, С1-С14 | C23: Громкоговорители и звуковые колонки | D23: РЦСМ | E23: Устройство | F23: 50 | G23: 400 | H23: 1 | I23: - | J23: 8 | M23: 31
B24: Итого по бригаде (явочная/списочная) численность: | H24: 1 | I24: 0 | J24: 8 | M24: 32
B25: Бригада по обслуживанию устройств СРС РОРС: РЦСС-18 | M25: 33
B26: ст. А, Б, С1-С14 | C26: Громкоговорители и звуковые колонки | D26: РЦСМ | E26: Устройство | F26: 50 | G26: 400 | H26: 1 | I26: - | J26: 8 | L26: Итого по ЛПУ связи 4:
B27: Итого по бригаде (явочная/списочная) численность: | H27: 1 | I27: 0 | J27: 8 | L27: Всего по ЛПУ связи 4:
B28: Бригада по обслуживанию устройств СРС РОРС: РЦСС-19
B29: ст. А, Б, С1-С14 | C29: Громкоговорители и звуковые колонки | D29: РЦСМ | E29: Устройство | F29: 50 | G29: 400 | H29: 1 | I29: - | J29: 8
B30: Итого по бригаде (явочная/списочная) численность: | H30: 1 | I30: 0 | J30: 8
B31: Бригада по ремонту и замене аппаратуры радиосвязи: РЦСС-20
B32: ст. А, Б, С1-С14 | C32: Устройства поездной радиосвязи | D32: РЦСН | E32: Р/ст. локом. | F32: 120 | G32: =450+14 -> 464 | H32: 1 | I32: 4 | J32: -
D33: РЦСН | E33: Р/ст. станционар. | F33: 220 | G33: =95+14 -> 109 | I33: 1 | J33: -
C34: Распорядительные станции поездной радиосвязи | D34: РЦСН | E34: Станция | F34: 290 | G34: =5+2 -> 7 | I34: 1 | J34: -
C35: Станционная и ремонтно-оперативная радиосвязь | D35: РЦСН | E35: Р/ст. локом. | F35: 200 | G35: =25+14 -> 39 | I35: 1 | J35: -
D36: РЦСН | E36: Р/ст. стационар. | F36: 180 | G36: =85+14 -> 99 | I36: 1 | J36: -
D37: РЦСН | E37: Р/ст. носимая | F37: 600 | G37: =40+40+14*10 -> 220 | I37: 1 | J37: -
D38: РЦСН | E38: Усилитель 600, 1000 Вт | F38: 197 | G38: =2+2+14+14 -> 32 | I38: 1 | J38: -
B39: Итого по бригаде (явочная/списочная) численность: | H39: 1 | I39: 10 | J39: 0
B40: Бригада по ремонту и замене аппаратуры радиосвязи: РЦСС-21
B41: ст. А, Б, С1-С14 | C41: Аппаратура для регистрации служебных разговоров | D41: РЦСН | E41: Комплект | F41: 35 | G41: =7+4+2*14 -> 39 | H41: 1 | I41: 2 | J41: -
...

Sheet + ЛПУ РДС
B2: Станции | C2: Обслуживаемые устройства связи | D2: Исполнитель | E2: Измеритель | F2: Норма обслуживания | G2: N | H2: Нормативная численность
H3: РЦСС | I3: РЦСН | J3: РЦСМ
B4: Бригада по обслуживанию устройств ПРС: РЦСС - 14
B5: ст. А, Б, С1-С14 | C5: Устройства поездной радиосвязи | D5: РЦСН | E5: Р/ст. локомот. "своих" | F5: 60 | G5: 450 | I5: 8 | J5: -
D6: РЦСН | E6: Распоряд. станция | F6: 105 | G6: =5+2*15 -> 35 | I6: 1 | J6: -
D7: РЦСН | E7: Р/ст. стационар. | F7: 45 | G7: =95+15 -> 110 | I7: 3 | J7: -
B8: Бригада по обслуживанию устройств СРС РОРС: РЦСС-15
B9: ст. А, Б, С1-С14 | C9: Радиостанция локомотивная | D9: РЦСН | E9: Р/ст. | F9: 60 | I9: =G9/F9 -> 0 | J9: -
C10: Распорядительные станции | D10: РЦСН | E10: Станция | F10: 80 | G10: =2+15 -> 17 | I10: =G10/F10 -> 0.2125 | J10: -
C11: Радиостанция стационарная | D11: РЦСН | E11: Р/ст. | F11: 75 | G11: =95+15 -> 110 | I11: =G11/F11 -> 1.4666667 | J11: -
C12: Радиостанция носимая | D12: РЦСМ | E12: Р/ст. | F12: 200 | G12: =40+40+10*14 -> 220 | I12: - | J12: =G12/F12 -> 1.1
C13: Усилитель 600, 1000 Вт | D13: РЦСН | E13: Усилитель | F13: 20 | G13: =2+2+2*14 -> 32 | I13: =G13/F13 -> 1.6 | J13: -
C14: Аппаратура для регистрации служебных разговоров | D14: РЦСН | E14: Комплект | F14: 15 | G14: =2*16 -> 32 | I14: =G14/F14 -> 2.1333333 | J14: -
C15: Громкоговорители и звуковые колонки | D15: РЦСМ | E15: Устройство | F15: 50 | G15: =66+66+(50*14)+93+81+(32*14) -> 1454 | I15: - | J15: =G15/F15 -> 29.08
C16: Речевые информаторы | D16: РЦСМ | E16: Комплект | F16: 25 | G16: 53 | I16: - | J16: =G16/F16 -> 2.12
B17: Бригада по ремонту и замене аппаратуры радиосвязи: РЦСС-22
B18: ст. А, Б, С1-С14 | C18: Устройства поездной радиосвязи | D18: РЦСН | E18: Р/ст. локом. | F18: 120 | I18: =G18/F18 -> 0 | J18: -
D19: РЦСН | E19: Р/ст. станционар. | F19: 220 | I19: =G19/F19 -> 0 | J19: -
C20: Распорядительные станции поездной радиосвязи | D20: РЦСН | E20: Станция | F20: 290 | I20: =G20/F20 -> 0 | J20: -
C21: Станционная и ремонтно-оперативная радиосвязь | D21: РЦСН | E21: Р/ст. локом. | F21: 200 | I21: =G21/F21 -> 0 | J21: -
D22: РЦСН | E22: Р/ст. стационар. | F22: 180 | I22: =G22/F22 -> 0 | J22: -
D23: РЦСН | E23: Р/ст. носимая | F23: 600 | I23: =G23/F23 -> 0 | J23: -
D24: РЦСН | E24: Усилитель 600, 1000 Вт | F24: 195 | I24: =G24/F24 -> 0 | J24: -
C25: Аппаратура для регистрации служебных разговоров | D25: РЦСН | E25: Комплект | F25: 35 | I25: =G25/F25 -> 0 | J25: -
C26: Громкоговорители и звуковые колонки | D26: РЦСН | E26: Устройство | F26: 95 | I26: =G26/F26 -> 0 | J26: -
C27: Речевые информаторы | D27: РЦСН | E27: Комплект | F27: 100 | I27: =G27/F27 -> 0 | J27: -

Sheet ч.ш. РТУ
B1: 1 группа | H1: 2 группа | N1: 4 группа
B2: Бригада по поверке и ремонту измерительных приборов | H2: Бригада по поверке и ремонту измерительных приборов | N2: Бригада по поверке и ремонту измерительных приборов
B3: Должность | C3: Измеритель | D3: Норма обслуживания | E3: N | F3: Нормативная численность | H3: Должность | I3: Измеритель | J3: Норма обслуживания | K3: N | L3: Нормативная численность | N3: Должность | O3: Измеритель | P3: Норма обслуживания | Q3: N | R3: Нормативная численность
B4: Инженер по поверке и ремонту измерительных приборов | C4: Прибор | D4: 1210 | F4: =E4/D4 -> 0 | H4: Инженер по поверке и ремонту измерительных приборов | I4: Прибор | J4: 1210 | L4: =K4/J4 -> 0 | N4: Инженер по поверке и ремонту измерительных приборов | O4: Прибор | P4: 1210 | R4: =Q4/P4 -> 0
B5: Электромеханник по проверке и ремонту измерительных приборов | C5: Прибор | D5: 770 | F5: =E5/D5 -> 0 | H5: Электромеханник по проверке и ремонту измерительных приборов | I5: Прибор | J5: 770 | L5: =K5/J5 -> 0 | N5: Электромеханник по проверке и ремонту измерительных приборов | O5: Прибор | P5: 770 | R5: =Q5/P5 -> 0
B6: Итого явочная численность | H6: Итого явочная численность | N6: Итого явочная численность
B7: Итого списочная численность | H7: Итого списочная численность | N7: Итого списочная численность
B8: РЦСС | H8: РЦСС | N8: РЦСС
B9: Всего по бригаде (РЦСС и подчиненных | H9: Всего по бригаде (РЦСС и подчиненных | N9: Всего по бригаде (РЦСС и подчиненных
B11: Бригада по измерению кабеля связи, испытанию защитных средств и проверке бесконтактной аппаратуры | H11: Бригада по измерению кабеля связи, испытанию защитных средств и проверке бесконтактной аппаратуры | N11: Бригада по измерению кабеля связи, испытанию защитных средств и проверке бесконтактной аппаратуры
B12: Должность | C12: Измеритель | D12: Норма обслуживания | E12: N | F12: Нормативная численность | H12: Должность | I12: Измеритель | J12: Норма обслуживания | K12: N | L12: Нормативная численность | N12: Должность | O12: Измеритель | P12: Норма обслуживания | Q12: N | R12: Нормативная численность
B13: Электромеханник по испытанию защитных средств и инструмента | C13: Жил·км | D13: 30000 | F13: =E13/D13 -> 0 | H13: Электромеханник по испытанию защитных средств и инструмента | I13: Жил·км | J13: 30000 | L13: =K13/J13 -> 0 | N13: Электромеханник по испытанию защитных средств и инструмента | O13: Жил·км | P13: 30000 | R13: =Q13/P13 -> 0
B14: Электромонтер по испытанию защитных средств и инструмента | C14: Жил·км | D14: 60000 | F14: =E14/D14 -> 0 | H14: Электромонтер по испытанию защитных средств и инструмента | I14: Жил·км | J14: 60000 | L14: =K14/J14 -> 0 | N14: Электромонтер по испытанию защитных средств и инструмента | O14: Жил·км | P14: 60000 | R14: =Q14/P14 -> 0
B15: Электромеханник по измерению и ремонту кабеля связи | C15: Дистанция | D15: 1 | F15: =E15/D15 -> 0 | H15: Электромеханник по измерению и ремонту кабеля связи | I15: Дистанция | J15: 1 | L15: =K15/J15 -> 0 | N15: Электромеханник по измерению и ремонту кабеля связи | O15: Дистанция | P15: 1 | R15: =Q15/P15 -> 0
B16: Электромонтер по измерению и ремонту кабеля связи | C16: Дистанция | D16: 1 | F16: =E16/D16 -> 0 | H16: Электромонтер по измерению и ремонту кабеля связи | I16: Дистанция | J16: 1 | L16: =K16/J16 -> 0 | N16: Электромонтер по измерению и ремонту кабеля связи | O16: Дистанция | P16: 1 | R16: =Q16/P16 -> 0
B17: Электромеханник по проверке и ремонту бесконтактной аппаратуры | C17: Прибор | D17: 11500 | F17: =E17/D17 -> 0 | H17: Электромеханник по проверке и ремонту бесконтактной аппаратуры | I17: Прибор | J17: 11500 | L17: =K17/J17 -> 0 | N17: Электромеханник по проверке и ремонту бесконтактной аппаратуры | O17: Прибор | P17: 11500 | R17: =Q17/P17 -> 0
B18: Электромонтер по проверке и ремонту бесконтактной аппаратуры | C18: Прибор | D18: 23000 | F18: =E18/D18 -> 0 | H18: Электромонтер по проверке и ремонту бесконтактной аппаратуры | I18: Прибор | J18: 23000 | L18: =K18/J18 -> 0 | N18: Электромонтер по проверке и ремонту бесконтактной аппаратуры | O18: Прибор | P18: 23000 | R18: =Q18/P18 -> 0
B19: Итого явочная численность | H19: Итого явочная численность | N19: Итого явочная численность
B20: Итого списочная численность | H20: Итого списочная численность | N20: Итого списочная численность
B21: РЦСС | H21: РЦСС | N21: РЦСС
B22: Всего по бригаде (РЦСС и подчиненных | H22: Всего по бригаде (РЦСС и подчиненных | N22: Всего по бригаде (РЦСС и подчиненных
B24: Бригада по ведению технической документации и паспортизации устройств связи | H24: Бригада по ведению технической документации и паспортизации устройств связи | N24: Бригада по ведению технической документации и паспортизации устройств связи
B25: Должность | C25: Измеритель | D25: Норма обслуживания | E25: N | F25: Нормативная численность | H25: Должность | I25: Измеритель | J25: Норма обслуживания | K25: N | L25: Нормативная численность | N25: Должность | O25: Измеритель | P25: Норма обслуживания | Q25: N | R25: Нормативная численность
B26: Инженер по эксплуатации технических средств | C26: 100 номеров АТС, р/ст. | D26: 1680 | F26: =E26/D26 -> 0 | H26: Инженер по эксплуатации технических средств | I26: 100 номеров АТС, р/ст. | J26: 1680 | L26: =K26/J26 -> 0 | N26: Инженер по эксплуатации технических средств | O26: 100 номеров АТС, р/ст. | P26: 1680 | R26: =Q26/P26 -> 0
B27: Итого явочная численность | H27: Итого явочная численность | N27: Итого явочная численность
B28: Итого списочная численность | H28: Итого списочная численность | N28: Итого списочная численность
B29: РЦСС | H29: РЦСС | N29: РЦСС
B30: Всего по бригаде (РЦСС и подчиненных | H30: Всего по бригаде (РЦСС и подчиненных | N30: Всего по бригаде (РЦСС и подчиненных
B32: Бригада по повышению надежности и обеспечению бесперебойной работы устройств связи | H32: Бригада по повышению надежности и обеспечению бесперебойной работы устройств связи | N32: Бригада по повышению надежности и обеспечению бесперебойной работы устройств связи
B33: Должность | C33: Измеритель | D33: Норма обслуживания | E33: N | F33: Нормативная численность | H33: Должность | I33: Измеритель | J33: Норма обслуживания | K33: N | L33: Нормативная численность | N33: Должность | O33: Измеритель | P33: Норма обслуживания | Q33: N | R33: Нормативная численность
B34: Инженер (диспетчер связи) | C34: Дистанция I группы | D34: 1 | F34: =E34/D34 -> 0 | H34: Инженер (диспетчер связи) | I34: Дистанция II группы | J34: 1 | L34: =K34/J34 -> 0 | N34: Электромеханник | O34: Канал св. 100 номеров АТС, р/ст. | P34: 2300 | R34: =Q34/P34 -> 0
B35: Электромеханник | C35: Канал св. 100 номеров АТС, р/ст. | D35: 2300 | F35: =E35/D35 -> 0 | H35: Электромеханник | I35: Канал св. 100 номеров АТС, р/ст. | J35: 2300 | L35: =K35/J35 -> 0 | N35: Итого явочная численность
B36: Итого явочная численность | H36: Итого явочная численность | N36: Итого списочная численность
B37: Итого списочная численность | H37: Итого списочная численность | N37: РЦСС
B38: РЦСС | H38: РЦСС | N38: Всего по бригаде (РЦСС и подчиненных)
B39: Всего по бригаде (РЦСС и подчиненных) | H39: Всего по бригаде (РЦСС и подчиненных)

Sheet ч. ш. ПБ
B1: 1 группа
B2: Численность работников аварийно-восстановительной летучки связи
B3: Должность | C3: Измеритель | D3: Норма обслуживания | E3: N | F3: Нормативная численность
B4: Электромеханник | C4: РСЦМ | D4: 9
B5: Электромонтер | C5: Провода·км ВЛС | D5: 2300
B6: Электромонтер | C6: Пара жил магистр. Кабеля | D6: 6000
B7: Итого явочная численность
B8: Итого списочная численность
B9: РЦСС
B10: Всего по бригаде (РЦСС и подчиненных)
B12: Численность работников дистанционной мастерской
B13: Должность | C13: Измеритель | D13: Норма обслуживания | E13: N | F13: Нормативная численность
B14: Электромеханник | C14: Канал св., 100 номеров АТС, р/ст | D14: 1850
B15: Электромонтер | D15: 1200
B16: Электромеханник-электроник | C16: Дистанция | D16: 1
B17: Итого явочная численность
B18: Итого списочная численность
B19: РЦСС
B20: Всего по бригаде (РЦСС и подчиненных)
B22: Численность работников участка механизации и автотранспорта
B23: Должность | C23: Измеритель | D23: Норма обслуживания | E23: N | F23: Нормативная численность
B24: Водитель автомобиля | C24: Автомобиль | D24: 1
B25: Тракторист | C25: Трактор | D25: 1
B26: Итого явочная численность
B27: Итого списочная численность
B28: РЦСС
B29: Всего по бригаде (РЦСС и подчиненных)

Sheet ч. ш. ТТС 
B2: Эксплуатационный штат телеграфно-телефонной станции
B3: ТТС станции | C3: Исполнитель | D3: Измеритель | E3: Норма обслуживания | F3: N | G3: Нормативная численность
B4: А | C4: Телеграфист | D4: АРМ-Т | E4: 1.3
B5: А | C5: Телефонист | D5: Канал связи | E5: 20
B6: А | C6: Почтальон | D6: ТТС | E6: 1
B7: Итого явочная численность
B8: Итого списочная численность
B9: РЦСС
B10: Всего по бригаде (РЦСС и подчиненных)
